Workbook

Sheet Source Data
A1: Data ID | B1: Research Area | C1: Indicator | D1: Location | E1: Segment | F1: Period | G1: Value (Avg Price) | H1: Unit | I1: Data_Type | J1: Source_Name | K1: Source_Url
A2: P001 | B2: Pricing | C2: 1-bed rent | D2: Yaba | E2: Mid-market | F2: 2026 | G2: 2500000 | H2: NGN/year | I2: Reported | J2: NPC | K2: https://nigeriapropertycentre.com/market-trends/average-prices/for-rent/flats-apartments/lagos/yaba?bedrooms=1
A3: P002 | B3: Pricing | C3: 2-bed rent | D3: Yaba | E3: Mid-market | F3: 2026 | G3: 4000000 | H3: NGN/year | I3: Reported | J3: NPC | K3: https://nigeriapropertycentre.com/market-trends/average-prices/for-rent/flats-apartments/lagos/yaba?bedrooms=2
A4: P003 | B4: Pricing | C4: 3-bed rent | D4: Yaba | E4: Mid-market | F4: 2026 | G4: 6000000 | H4: NGN/year | I4: Reported | J4: NPC | K4: https://nigeriapropertycentre.com/market-trends/average-prices/for-rent/flats-apartments/lagos/yaba?bedrooms=3
A5: P004 | B5: Pricing | C5: 1-bed rent | D5: Yaba | E5: Mid-market | F5: 2025 | G5: 1800000 | H5: NGN/year | I5: Reported | J5: NPC | K5: https://nigeriapropertycentre.com/market-trends/average-prices/for-rent/flats-apartments/lagos/yaba?bedrooms=1
A6: P005 | B6: Pricing | C6: 2-bed rent | D6: Yaba | E6: Mid-market | F6: 2025 | G6: 3000000 | H6: NGN/year | I6: Reported | J6: NPC | K6: https://nigeriapropertycentre.com/market-trends/average-prices/for-rent/flats-apartments/lagos/yaba?bedrooms=2
A7: P006 | B7: Pricing | C7: 3-bed rent | D7: Yaba | E7: Mid-market | F7: 2025 | G7: 4700000 | H7: NGN/year | I7: Reported | J7: NPC | K7: https://nigeriapropertycentre.com/market-trends/average-prices/for-rent/flats-apartments/lagos/yaba?bedrooms=3
A8: P007 | B8: Pricing | C8: 2-bed rent | D8: Yaba | E8: Mid-market | F8: 2024 | G8: 2500000 | H8: NGN/year | I8: Reported | J8: Zikan Properties | K8: https://www.zikanpropsolutions.com/post/the-2026-mainland-renaissance-yaba-surulere-and-the-red-line-effect
A9: P008 | B9: Pricing | C9: 2-bed rent | D9: Yaba | E9: Mid-market | F9: 2026 | G9: 4500000 - 5500000 | H9: NGN/year | I9: Reported | J9: Zikan Properties | K9: https://www.zikanpropsolutions.com/post/the-2026-mainland-renaissance-yaba-surulere-and-the-red-line-effect
A10: P009 | B10: Pricing | C10: 1-bed rent | D10: Surulere | E10: Mid-market | F10: 2025 | G10: 1700000 | H10: NGN/year | I10: Reported | J10: NPC | K10: https://nigeriapropertycentre.com/market-trends/average-prices/for-rent/flats-apartments/lagos/surulere?bedrooms=1
A11: P010 | B11: Pricing | C11: 2-bed rent | D11: Surulere | E11: Mid-market | F11: 2025 | G11: 3200000 | H11: NGN/year | I11: Reported | J11: NPC | K11: https://nigeriapropertycentre.com/market-trends/average-prices/for-rent/flats-apartments/lagos/surulere?bedrooms=2
A12: P011 | B12: Pricing | C12: 3-bed rent | D12: Surulere | E12: Mid-market | F12: 2025 | G12: 4000000 | H12: NGN/year | I12: Reported | J12: NPC | K12: https://nigeriapropertycentre.com/market-trends/average-prices/for-rent/flats-apartments/lagos/surulere?bedrooms=3
A13: P012 | B13: Pricing | C13: 1-bed rent | D13: Surulere | E13: Mid-market | F13: 2026 | G13: 2500000 | H13: NGN/year | I13: Reported | J13: NPC | K13: https://nigeriapropertycentre.com/market-trends/average-prices/for-rent/flats-apartments/lagos/surulere?bedrooms=1
A14: P013 | B14: Pricing | C14: 2-bed rent | D14: Surulere | E14: Mid-market | F14: 2026 | G14: 4000000 | H14: NGN/year | I14: Reported | J14: NPC | K14: https://nigeriapropertycentre.com/market-trends/average-prices/for-rent/flats-apartments/lagos/surulere?bedrooms=2
A15: P014 | B15: Pricing | C15: 3-bed rent | D15: Surulere | E15: Mid-market | F15: 2026 | G15: 5000000 | H15: NGN/year | I15: Reported | J15: NPC | K15: https://nigeriapropertycentre.com/market-trends/average-prices/for-rent/flats-apartments/lagos/surulere?bedrooms=3
A16: P015 | B16: Pricing | C16: 2-bed rent | D16: Surulere | E16: Mid-market | F16: 2024 | G16: 2200000 | H16: NGN/year | I16: Reported | J16: Zikan Properties | K16: https://www.zikanpropsolutions.com/post/the-2026-mainland-renaissance-yaba-surulere-and-the-red-line-effect
A17: P016 | B17: Pricing | C17: 2-bed rent | D17: Surulere | E17: Mid-market | F17: 2026 | G17: 4000000 - 5000000 | H17: NGN/year | I17: Reported | J17: Zikan Properties | K17: https://www.zikanpropsolutions.com/post/the-2026-mainland-renaissance-yaba-surulere-and-the-red-line-effect
A18: P017 | B18: Pricing | C18: 1-bed rent | D18: Gbagada | E18: Mid-market | F18: 2026 | G18: 2500000 | H18: NGN/year | I18: Reported | J18: NPC | K18: https://nigeriapropertycentre.com/market-trends/average-prices/for-rent/flats-apartments/lagos/gbagada?bedrooms=1
A19: P018 | B19: Pricing | C19: 2-bed rent | D19: Gbagada | E19: Mid-market | F19: 2026 | G19: 4500000 | H19: NGN/year | I19: Reported | J19: NPC | K19: https://nigeriapropertycentre.com/market-trends/average-prices/for-rent/flats-apartments/lagos/gbagada?bedrooms=2
A20: P019 | B20: Pricing | C20: 3-bed rent | D20: Gbagada | E20: Mid-market | F20: 2026 | G20: 7000000 | H20: NGN/year | I20: Reported | J20: NPC | K20: https://nigeriapropertycentre.com/market-trends/average-prices/for-rent/flats-apartments/lagos/gbagada?bedrooms=3
A21: P020 | B21: Pricing | C21: 1-bed rent | D21: Gbagada | E21: Mid-market | F21: 2025 | G21: 2000000 | H21: NGN/year | I21: Reported | J21: NPC | K21: https://nigeriapropertycentre.com/market-trends/average-prices/for-rent/flats-apartments/lagos/gbagada?bedrooms=1
A22: P021 | B22: Pricing | C22: 2-bed rent | D22: Gbagada | E22: Mid-market | F22: 2025 | G22: 3300000 | H22: NGN/year | I22: Reported | J22: NPC | K22: https://nigeriapropertycentre.com/market-trends/average-prices/for-rent/flats-apartments/lagos/gbagada?bedrooms=2
A23: P022 | B23: Pricing | C23: 3-bed rent | D23: Gbagada | E23: Mid-market | F23: 2025 | G23: 4500000 | H23: NGN/year | I23: Reported | J23: NPC | K23: https://nigeriapropertycentre.com/market-trends/average-prices/for-rent/flats-apartments/lagos/gbagada?bedrooms=3
A24: P023 | B24: Pricing | C24: 2-bed rent | D24: Gbagada | E24: Mid-market | F24: 2024 | G24: 2800000 | H24: NGN/year | I24: Reported | J24: Zikan Properties | K24: https://www.zikanpropsolutions.com/post/the-2026-mainland-renaissance-yaba-surulere-and-the-red-line-effect
A25: P024 | B25: Pricing | C25: 2-bed rent | D25: Gbagada | E25: Mid-market | F25: 2026 | G25: 4200000 | H25: NGN/year | I25: Reported | J25: Zikan Properties | K25: https://www.zikanpropsolutions.com/post/the-2026-mainland-renaissance-yaba-surulere-and-the-red-line-effect
A26: P025 | B26: Pricing | C26: 1-bed rent | D26: Ikeja | E26: Mid-market | F26: 2026 | G26: 2300000 | H26: NGN/year | I26: Reported | J26: NPC | K26: https://nigeriapropertycentre.com/market-trends/average-prices/for-rent/flats-apartments/lagos/ikeja?bedrooms=1
A27: P026 | B27: Pricing | C27: 2-bed rent | D27: Ikeja | E27: Mid-market | F27: 2026 | G27: 4000000 | H27: NGN/year | I27: Reported | J27: NPC | K27: https://nigeriapropertycentre.com/market-trends/average-prices/for-rent/flats-apartments/lagos/ikeja?bedrooms=2
A28: P027 | B28: Pricing | C28: 3-bed rent | D28: Ikeja | E28: Mid-market | F28: 2026 | G28: 8500000 | H28: NGN/year | I28: Reported | J28: NPC | K28: https://nigeriapropertycentre.com/market-trends/average-prices/for-rent/flats-apartments/lagos/ikeja?bedrooms=3
A29: P028 | B29: Pricing | C29: 1-bed rent | D29: Ikeja | E29: Mid-market | F29: 2025 | G29: 1800000 | H29: NGN/year | I29: Reported | J29: NPC | K29: https://nigeriapropertycentre.com/market-trends/average-prices/for-rent/flats-apartments/lagos/ikeja?bedrooms=1
... A136: M015 | B136: Macro | C136: MPR (year-end) | D136: Nigeria | E136: Mid-market | F136: 2025 | G136: 27 | H136: % | I136: Reported | J136: THISDAY/CBN | K136: https://www.thisdaylive.com/2026/02/23/mirroring-monetary-policy-maximum-lending-rate-droped-to-29-32-in-december/
A137: PO001 | B137: Policy | C137: Agency fee (letting) | D137: Lagos | E137: Mid-market | F137: Current | G137: 10 | H137: % of rent | I137: Reported | J137: LASRERA | K137: https://lasrera.lagosstate.gov.ng/resources/L28_LagosStateEstateAgencyRegulatoryAut_p04.pdf
A138: PO002 | B138: Policy | C138: Agency fee (sale) | D138: Lagos | E138: Mid-market | F138: Current | G138: 15 | H138: % of proceeds | I138: Reported | J138: LASRERA | K138: https://lasrera.lagosstate.gov.ng/resources/L28_LagosStateEstateAgencyRegulatoryAut_p04.pdf
A139: PO003 | B139: Policy | C139: Legal fee (stenancy) | D139: Lagos | E139: Mid-market | F139: Current | G139: 12.5 | H139: % of consideration | I139: Reported | J139: LASRERA | K139: https://lasrera.lagosstate.gov.ng/resources/L28_LagosStateEstateAgencyRegulatoryAut_p04.pdf
A140: PO004 | B140: Policy | C140: Advance rent limit (monthly) | D140: Lagos | E140: Mid-market | F140: 2025 | G140: 3 | H140: Months | I140: Reported | J140: Tenancy Bill 2025 | K140: https://www.templars-law.com/app/uploads/2025/12/The-Lagos-State-Tenancy-Bill-2025.pdf
A141: PO005 | B141: Policy | C141: Advance rent limit (yearly) | D141: Lagos | E141: Mid-market | F141: 2025 | G141: 1 | H141: Year | I141: Reported | J141: Tenancy Bill 2025 | K141: https://www.templars-law.com/app/uploads/2025/12/The-Lagos-State-Tenancy-Bill-2025.pdf
A142: PO006 | B142: Policy | C142: Agency commission cap | D142: Lagos | E142: Mid-market | F142: 2025 | G142: 5 | H142: % of rent | I142: Reported | J142: Tenancy Bill 2025 | K142: https://www.templars-law.com/app/uploads/2025/12/The-Lagos-State-Tenancy-Bill-2025.pdf
A143: PO007 | B143: Policy | C143: VAT on residential sales | D143: Nigeria | E143: Mid-market | F143: 2025 | G143: 0 | H143: % | I143: Reported | J143: NTA 2025 | K143: https://www.dlapiperrealworld.com/law/index.html?c=NG&s=taxation-of-real-estate-sales-and-purchases&t=sale-and-purchase
A144: PO008 | B144: Policy | C144: VAT on commercial property | D144: Nigeria | E144: Mid-market | F144: 2025 | G144: 7.5 | H144: % | I144: Reported | J144: NTA 2025 | K144: https://www.dlapiperrealworld.com/law/index.html?c=NG&s=taxation-of-real-estate-sales-and-purchases&t=sale-and-purchase
A145: PO009 | B145: Policy | C145: Consent fee | D145: Lagos | E145: Mid-market | F145: 2025 | G145: 1.5 | H145: % | I145: Reported | J145: NTA 2025 | K145: https://www.dlapiperrealworld.com/law/index.html?c=NG&s=taxation-of-real-estate-sales-and-purchases&t=sale-and-purchase
A146: PO010 | B146: Policy | C146: Registration fee | D146: Lagos | E146: Mid-market | F146: 2025 | G146: 0.5 | H146: % | I146: Reported | J146: NTA 2025 | K146: https://www.dlapiperrealworld.com/law/index.html?c=NG&s=taxation-of-real-estate-sales-and-purchases&t=sale-and-purchase
...

Sheet Clean Data
A1: Data ID | B1: Research Area | C1: Indicator | D1: Location | E1: Period | F1: Value | G1: Numeric? | H1: Unit | I1: Source | J1: Source Url
A2: P001 | B2: Pricing | C2: 1-bed rent | D2: Yaba | E2: 2026 | F2: 2500000 | G2: =IF(ISNUMBER(F2),"Yes","No") -> Yes | H2: NGN/year | I2: NPC | J2: https://nigeriapropertycentre.com/market-trends/average-prices/for-rent/flats-apartments/lagos/yaba?bedrooms=1
A3: P002 | B3: Pricing | C3: 2-bed rent | D3: Yaba | E3: 2026 | F3: 4000000 | G3: =IF(ISNUMBER(F3),"Yes","No") -> Yes | H3: NGN/year | I3: NPC | J3: https://nigeriapropertycentre.com/market-trends/average-prices/for-rent/flats-apartments/lagos/yaba?bedrooms=2
A4: P003 | B4: Pricing | C4: 3-bed rent | D4: Yaba | E4: 2026 | F4: 6000000 | G4: =IF(ISNUMBER(F4),"Yes","No") -> Yes | H4: NGN/year | I4: NPC | J4: https://nigeriapropertycentre.com/market-trends/average-prices/for-rent/flats-apartments/lagos/yaba?bedrooms=3
A5: P004 | B5: Pricing | C5: 1-bed rent | D5: Yaba | E5: 2025 | F5: 1800000 | G5: =IF(ISNUMBER(F5),"Yes","No") -> Yes | H5: NGN/year | I5: NPC | J5: https://nigeriapropertycentre.com/market-trends/average-prices/for-rent/flats-apartments/lagos/yaba?bedrooms=1
A6: P005 | B6: Pricing | C6: 2-bed rent | D6: Yaba | E6: 2025 | F6: 3000000 | G6: =IF(ISNUMBER(F6),"Yes","No") -> Yes | H6: NGN/year | I6: NPC | J6: https://nigeriapropertycentre.com/market-trends/average-prices/for-rent/flats-apartments/lagos/yaba?bedrooms=2
A7: P006 | B7: Pricing | C7: 3-bed rent | D7: Yaba | E7: 2025 | F7: 4700000 | G7: =IF(ISNUMBER(F7),"Yes","No") -> Yes | H7: NGN/year | I7: NPC | J7: https://nigeriapropertycentre.com/market-trends/average-prices/for-rent/flats-apartments/lagos/yaba?bedrooms=3
A8: P007 | B8: Pricing | C8: 2-bed rent | D8: Yaba | E8: 2024 | F8: 2500000 | G8: =IF(ISNUMBER(F8),"Yes","No") -> Yes | H8: NGN/year | I8: Zikan Properties | J8: https://www.zikanpropsolutions.com/post/the-2026-mainland-renaissance-yaba-surulere-and-the-red-line-effect
A9: P008 | B9: Pricing | C9: 2-bed rent | D9: Yaba | E9: 2026 | F9: 5000000 | G9: =IF(ISNUMBER(F9),"Yes","No") -> Yes | H9: NGN/year | I9: Zikan Properties | J9: https://www.zikanpropsolutions.com/post/the-2026-mainland-renaissance-yaba-surulere-and-the-red-line-effect
A10: P009 | B10: Pricing | C10: 1-bed rent | D10: Surulere | E10: 2025 | F10: 1700000 | G10: =IF(ISNUMBER(F10),"Yes","No") -> Yes | H10: NGN/year | I10: NPC | J10: https://nigeriapropertycentre.com/market-trends/average-prices/for-rent/flats-apartments/lagos/surulere?bedrooms=1
A11: P010 | B11: Pricing | C11: 2-bed rent | D11: Surulere | E11: 2025 | F11: 3200000 | G11: =IF(ISNUMBER(F11),"Yes","No") -> Yes | H11: NGN/year | I11: NPC | J11: https://nigeriapropertycentre.com/market-trends/average-prices/for-rent/flats-apartments/lagos/surulere?bedrooms=2
A12: P011 | B12: Pricing | C12: 3-bed rent | D12: Surulere | E12: 2025 | F12: 4000000 | G12: =IF(ISNUMBER(F12),"Yes","No") -> Yes | H12: NGN/year | I12: NPC | J12: https://nigeriapropertycentre.com/market-trends/average-prices/for-rent/flats-apartments/lagos/surulere?bedrooms=3
A13: P012 | B13: Pricing | C13: 1-bed rent | D13: Surulere | E13: 2026 | F13: 2500000 | G13: =IF(ISNUMBER(F13),"Yes","No") -> Yes | H13: NGN/year | I13: NPC | J13: https://nigeriapropertycentre.com/market-trends/average-prices/for-rent/flats-apartments/lagos/surulere?bedrooms=1
... A150: CO001 | B150: Competitive | C150: Locations covered | D150: Lagos | E150: 2026 | F150: 10 | G150: =IF(ISNUMBER(F150),"Yes","No") -> Yes | H150: Locations | I150: Citiliving | J150: https://thecitiliving.com/about-us/
A151: CO002 | B151: Competitive | C151: Target segment | D151: Lagos | E151: 2026 | F151: Middle-income | G151: =IF(ISNUMBER(F151),"Yes","No") -> No | H151: Segment | I151: Citiliving | J151: https://thecitiliving.com/about-us/
A152: CO003 | B152: Competitive | C152: Project Location | D152: Sangotedo (Ajah) | E152: 2026 | F152: South Point Estate | G152: =IF(ISNUMBER(F152),"Yes","No") -> No | H152: Project | I152: Royal Colony | J152: https://thesun.ng/our-mission-is-to-turn-investments-into-legacies-says-oladigbolu/
A153: CO004 | B153: Competitive | C153: Target segment | D153: Lagos | E153: 2026 | F153: Middle-income | G153: =IF(ISNUMBER(F153),"Yes","No") -> No | H153: Segment | I153: Royal Colony | J153: https://thesun.ng/our-mission-is-to-turn-investments-into-legacies-says-oladigbolu/
A154: CO005 | B154: Competitive | C154: Former name | D154: Lagos | E154: 2025 | F154: Northcourt | G154: =IF(ISNUMBER(F154),"Yes","No") -> No | H154: Name | I154: Daily Trust | J154: https://dailytrust.com/northcourt-rebrands-as-panterra-real-estate-group/
A155: CO006 | B155: Competitive | C155: Structure | D155: Lagos | E155: 2026 | F155: Panterra Real Estate Group | G155: =IF(ISNUMBER(F155),"Yes","No") -> No | H155: Company | I155: Daily Trust | J155: https://dailytrust.com/northcourt-rebrands-as-panterra-real-estate-group/
A156: CO007 | B156: Competitive | C156: Focus areas | D156: Lagos | E156: 2026 | F156: Investment, asset management, research | G156: =IF(ISNUMBER(F156),"Yes","No") -> No | H156: Focus | I156: Daily Trust | J156: https://dailytrust.com/northcourt-rebrands-as-panterra-real-estate-group/
A157: CO008 | B157: Competitive | C157: Business model | D157: Lagos | E157: 2026 | F157: Rent-to-own | G157: =IF(ISNUMBER(F157),"Yes","No") -> No | H157: Model | I157: Mixta Africa | J157: https://businessday.ng/real-estate/article/5-developers-that-make-tenants-landlords-by-paying-tenured-rents/
A158: CO009 | B158: Competitive | C158: Target segment | D158: Lagos | E158: 2026 | F158: Middle-income | G158: =IF(ISNUMBER(F158),"Yes","No") -> No | H158: Segment | I158: Mixta Africa | J158: https://businessday.ng/real-estate/article/5-developers-that-make-tenants-landlords-by-paying-tenured-rents/
A159: CO010 | B159: Competitive | C159: Business model | D159: Lagos | E159: 2026 | F159: Rent4Less, Rent-to-Own | G159: =IF(ISNUMBER(F159),"Yes","No") -> No | H159: Model | I159: Alpha Mead | J159: https://businessday.ng/real-estate/article/5-developers-that-make-tenants-landlords-by-paying-tenured-rents/
A160: CO011 | B160: Competitive | C160: Target segment | D160: Lagos | E160: 2026 | F160: Mid-income tenants | G160: =IF(ISNUMBER(F160),"Yes","No") -> No | H160: Segment | I160: Alpha Mead | J160: https://businessday.ng/real-estate/article/5-developers-that-make-tenants-landlords-by-paying-tenured-rents/
A161: CO012 | B161: Competitive | C161: Project | D161: Ibeju-Lekki | E161: 2026 | F161: Alexandra Courts Estate | G161: =IF(ISNUMBER(F161),"Yes","No") -> No | H161: Project | I161: Legrande | J161: https://businessday.ng/real-estate/article/5-developers-that-make-tenants-landlords-by-paying-tenured-rents/
A162: CO013 | B162: Competitive | C162: Units planned | D162: Ibeju-Lekki | E162: 2026 | F162: 5000 | G162: =IF(ISNUMBER(F162),"Yes","No") -> Yes | H162: Units | I162: Legrande | J162: https://businessday.ng/real-estate/article/5-developers-that-make-tenants-landlords-by-paying-tenured-rents/
A163: CO014 | B163: Competitive | C163: Project | D163: Idera, Lagos | E163: 2026 | F163: Capital Gardens Estate | G163: =IF(ISNUMBER(F163),"Yes","No") -> No | H163: Project | I163: Victoria Crest | J163: https://guardian.ng/property/firm-targets-middle-class-in-new-housing-development/
A164: CO015 | B164: Competitive | C164: Units planned | D164: Idera, Lagos | E164: 2026 | F164: 400 | G164: =IF(ISNUMBER(F164),"Yes","No") -> Yes | H164: Units | I164: Victoria Crest | J164: https://guardian.ng/property/firm-targets-middle-class-in-new-housing-development/
A165: CO016 | B165: Competitive | C165: Target segment | D165: Lagos | E165: 2026 | F165: Middle-class | G165: =IF(ISNUMBER(F165),"Yes","No") -> No | H165: Segment | I165: Victoria Crest | J165: https://guardian.ng/property/firm-targets-middle-class-in-new-housing-development/
A166: CO017 | B166: Competitive | C166: Demand drivers | D166: Yaba | E166: 2026 | F166: Education, technology, Island access | G166: =IF(ISNUMBER(F166),"Yes","No") -> No | H166: Drivers | I166: Estate Intel | J166: https://estateintel.com/reports/residential-pipeline-activity-in-yaba

Sheet Analysis
A1: Location | B1: Unit | C1: 2025 Rent (Average) | D1: 2026 Rent (Average) | E1: 2025 Sale Price (Average) | F1: 2026 Sale Price (Average) | G1: YoY Rent Growth | H1: YoY Price Growth | I1: Gross Rental Yield (2026, Before Expenses) | J1: Price-to-Rent Ratio (2026)
A2: Yaba | B2: 1-bed | C2: =AVERAGEIFS('Clean Data'!$F:$F, 'Clean Data'!$B:$B, "Pricing", 'Clean Data'!$C:$C, B2&" rent", 'Clean Data'!$D:$D, A2, 'Clean Data'!$E:$E, 2025) -> 1800000 | D2: =AVERAGEIFS('Clean Data'!$F:$F, 'Clean Data'!$B:$B, "Pricing", 'Clean Data'!$C:$C, B2&" rent", 'Clean Data'!$D:$D, A2, 'Clean Data'!$E:$E, 2026) -> 2500000 | E2: =AVERAGEIFS('Clean Data'!$F:$F, 'Clean Data'!$B:$B, "Pricing", 'Clean Data'!$C:$C, B2&" flat sale price", 'Clean Data'!$D:$D, A2, 'Clean Data'!$E:$E, 2025) -> 50000000 | F2: =AVERAGEIFS('Clean Data'!$F:$F, 'Clean Data'!$B:$B, "Pricing", 'Clean Data'!$C:$C, B2&" flat sale price", 'Clean Data'!$D:$D, A2, 'Clean Data'!$E:$E, 2026) -> 58000000 | G2: =IFERROR((D2-C2)/C2, "") -> 0.38888889 | H2: =IFERROR((F2-E2)/E2, "") -> 0.16 | I2: =IFERROR(D2/F2, "") -> 0.043103448 | J2: =IFERROR(F2/D2, "") -> 23.2
A3: Yaba | B3: 2-bed | C3: =AVERAGEIFS('Clean Data'!$F:$F, 'Clean Data'!$B:$B, "Pricing", 'Clean Data'!$C:$C, B3&" rent", 'Clean Data'!$D:$D, A3, 'Clean Data'!$E:$E, 2025) -> 3000000 | D3: =AVERAGEIFS('Clean Data'!$F:$F, 'Clean Data'!$B:$B, "Pricing", 'Clean Data'!$C:$C, B3&" rent", 'Clean Data'!$D:$D, A3, 'Clean Data'!$E:$E, 2026) -> 4500000 | E3: =AVERAGEIFS('Clean Data'!$F:$F, 'Clean Data'!$B:$B, "Pricing", 'Clean Data'!$C:$C, B3&" flat sale price", 'Clean Data'!$D:$D, A3, 'Clean Data'!$E:$E, 2025) -> 85000000 | F3: =AVERAGEIFS('Clean Data'!$F:$F, 'Clean Data'!$B:$B, "Pricing", 'Clean Data'!$C:$C, B3&" flat sale price", 'Clean Data'!$D:$D, A3, 'Clean Data'!$E:$E, 2026) -> 140000000 | G3: =IFERROR((D3-C3)/C3, "") -> 0.5 | H3: =IFERROR((F3-E3)/E3, "") -> 0.64705882 | I3: =IFERROR(D3/F3, "") -> 0.032142857 | J3: =IFERROR(F3/D3, "") -> 31.111111
A4: Yaba | B4: 3-bed | C4: =AVERAGEIFS('Clean Data'!$F:$F, 'Clean Data'!$B:$B, "Pricing", 'Clean Data'!$C:$C, B4&" rent", 'Clean Data'!$D:$D, A4, 'Clean Data'!$E:$E, 2025) -> 4700000 | D4: =AVERAGEIFS('Clean Data'!$F:$F, 'Clean Data'!$B:$B, "Pricing", 'Clean Data'!$C:$C, B4&" rent", 'Clean Data'!$D:$D, A4, 'Clean Data'!$E:$E, 2026) -> 6000000 | E4: =AVERAGEIFS('Clean Data'!$F:$F, 'Clean Data'!$B:$B, "Pricing", 'Clean Data'!$C:$C, B4&" flat sale price", 'Clean Data'!$D:$D, A4, 'Clean Data'!$E:$E, 2025) -> 150000000 | F4: =AVERAGEIFS('Clean Data'!$F:$F, 'Clean Data'!$B:$B, "Pricing", 'Clean Data'!$C:$C, B4&" flat sale price", 'Clean Data'!$D:$D, A4, 'Clean Data'!$E:$E, 2026) -> 170000000 | G4: =IFERROR((D4-C4)/C4, "") -> 0.27659574 | H4: =IFERROR((F4-E4)/E4, "") -> 0.13333333 | I4: =IFERROR(D4/F4, "") -> 0.035294118 | J4: =IFERROR(F4/D4, "") -> 28.333333
A5: Surulere | B5: 1-bed | C5: =AVERAGEIFS('Clean Data'!$F:$F, 'Clean Data'!$B:$B, "Pricing", 'Clean Data'!$C:$C, B5&" rent", 'Clean Data'!$D:$D, A5, 'Clean Data'!$E:$E, 2025) -> 1700000 | D5: =AVERAGEIFS('Clean Data'!$F:$F, 'Clean Data'!$B:$B, "Pricing", 'Clean Data'!$C:$C, B5&" rent", 'Clean Data'!$D:$D, A5, 'Clean Data'!$E:$E, 2026) -> 2500000 | E5: =AVERAGEIFS('Clean Data'!$F:$F, 'Clean Data'!$B:$B, "Pricing", 'Clean Data'!$C:$C, B5&" flat sale price", 'Clean Data'!$D:$D, A5, 'Clean Data'!$E:$E, 2025) -> 78000000 | F5: =AVERAGEIFS('Clean Data'!$F:$F, 'Clean Data'!$B:$B, "Pricing", 'Clean Data'!$C:$C, B5&" flat sale price", 'Clean Data'!$D:$D, A5, 'Clean Data'!$E:$E, 2026) -> 75000000 | G5: =IFERROR((D5-C5)/C5, "") -> 0.47058824 | H5: =IFERROR((F5-E5)/E5, "") -> -0.038461538 | I5: =IFERROR(D5/F5, "") -> 0.033333333 | J5: =IFERROR(F5/D5, "") -> 30
A6: Surulere | B6: 2-bed | C6: =AVERAGEIFS('Clean Data'!$F:$F, 'Clean Data'!$B:$B, "Pricing", 'Clean Data'!$C:$C, B6&" rent", 'Clean Data'!$D:$D, A6, 'Clean Data'!$E:$E, 2025) -> 3200000 | D6: =AVERAGEIFS('Clean Data'!$F:$F, 'Clean Data'!$B:$B, "Pricing", 'Clean Data'!$C:$C, B6&" rent", 'Clean Data'!$D:$D, A6, 'Clean Data'!$E:$E, 2026) -> 4250000 | E6: =AVERAGEIFS('Clean Data'!$F:$F, 'Clean Data'!$B:$B, "Pricing", 'Clean Data'!$C:$C, B6&" flat sale price", 'Clean Data'!$D:$D, A6, 'Clean Data'!$E:$E, 2025) -> 100000000 | F6: =AVERAGEIFS('Clean Data'!$F:$F, 'Clean Data'!$B:$B, "Pricing", 'Clean Data'!$C:$C, B6&" flat sale price", 'Clean Data'!$D:$D, A6, 'Clean Data'!$E:$E, 2026) -> 110000000 | G6: =IFERROR((D6-C6)/C6, "") -> 0.328125 | H6: =IFERROR((F6-E6)/E6, "") -> 0.1 | I6: =IFERROR(D6/F6, "") -> 0.038636364 | J6: =IFERROR(F6/D6, "") -> 25.882353
A7: Surulere | B7: 3-bed | C7: =AVERAGEIFS('Clean Data'!$F:$F, 'Clean Data'!$B:$B, "Pricing", 'Clean Data'!$C:$C, B7&" rent", 'Clean Data'!$D:$D, A7, 'Clean Data'!$E:$E, 2025) -> 4000000 | D7: =AVERAGEIFS('Clean Data'!$F:$F, 'Clean Data'!$B:$B, "Pricing", 'Clean Data'!$C:$C, B7&" rent", 'Clean Data'!$D:$D, A7, 'Clean Data'!$E:$E, 2026) -> 5000000 | E7: =AVERAGEIFS('Clean Data'!$F:$F, 'Clean Data'!$B:$B, "Pricing", 'Clean Data'!$C:$C, B7&" flat sale price", 'Clean Data'!$D:$D, A7, 'Clean Data'!$E:$E, 2025) -> 120000000 | F7: =AVERAGEIFS('Clean Data'!$F:$F, 'Clean Data'!$B:$B, "Pricing", 'Clean Data'!$C:$C, B7&" flat sale price", 'Clean Data'!$D:$D, A7, 'Clean Data'!$E:$E, 2026) -> 280000000 | G7: =IFERROR((D7-C7)/C7, "") -> 0.25 | H7: =IFERROR((F7-E7)/E7, "") -> 1.3333333 | I7: =IFERROR(D7/F7, "") -> 0.017857143 | J7: =IFERROR(F7/D7, "") -> 56
A8: Gbagada | B8: 1-bed | C8: =AVERAGEIFS('Clean Data'!$F:$F, 'Clean Data'!$B:$B, "Pricing", 'Clean Data'!$C:$C, B8&" rent", 'Clean Data'!$D:$D, A8, 'Clean Data'!$E:$E, 2025) -> 2000000 | D8: =AVERAGEIFS('Clean Data'!$F:$F, 'Clean Data'!$B:$B, "Pricing", 'Clean Data'!$C:$C, B8&" rent", 'Clean Data'!$D:$D, A8, 'Clean Data'!$E:$E, 2026) -> 2500000 | E8: =AVERAGEIFS('Clean Data'!$F:$F, 'Clean Data'!$B:$B, "Pricing", 'Clean Data'!$C:$C, B8&" flat sale price", 'Clean Data'!$D:$D, A8, 'Clean Data'!$E:$E, 2025) -> 15500000 | F8: =AVERAGEIFS('Clean Data'!$F:$F, 'Clean Data'!$B:$B, "Pricing", 'Clean Data'!$C:$C, B8&" flat sale price", 'Clean Data'!$D:$D, A8, 'Clean Data'!$E:$E, 2026) -> 21000000 | G8: =IFERROR((D8-C8)/C8, "") -> 0.25 | H8: =IFERROR((F8-E8)/E8, "") -> 0.35483871 | I8: =IFERROR(D8/F8, "") -> 0.11904762 | J8: =IFERROR(F8/D8, "") -> 8.4
A9: Gbagada | B9: 2-bed | C9: =AVERAGEIFS('Clean Data'!$F:$F, 'Clean Data'!$B:$B, "Pricing", 'Clean Data'!$C:$C, B9&" rent", 'Clean Data'!$D:$D, A9, 'Clean Data'!$E:$E, 2025) -> 3300000 | D9: =AVERAGEIFS('Clean Data'!$F:$F, 'Clean Data'!$B:$B, "Pricing", 'Clean Data'!$C:$C, B9&" rent", 'Clean Data'!$D:$D, A9, 'Clean Data'!$E:$E, 2026) -> 4350000 | E9: =AVERAGEIFS('Clean Data'!$F:$F, 'Clean Data'!$B:$B, "Pricing", 'Clean Data'!$C:$C, B9&" flat sale price", 'Clean Data'!$D:$D, A9, 'Clean Data'!$E:$E, 2025) -> 55000000 | F9: =AVERAGEIFS('Clean Data'!$F:$F, 'Clean Data'!$B:$B, "Pricing", 'Clean Data'!$C:$C, B9&" flat sale price", 'Clean Data'!$D:$D, A9, 'Clean Data'!$E:$E, 2026) -> 85000000 | G9: =IFERROR((D9-C9)/C9, "") -> 0.31818182 | H9: =IFERROR((F9-E9)/E9, "") -> 0.54545455 | I9: =IFERROR(D9/F9, "") -> 0.051176471 | J9: =IFERROR(F9/D9, "") -> 19.54023
A10: Gbagada | B10: 3-bed | C10: =AVERAGEIFS('Clean Data'!$F:$F, 'Clean Data'!$B:$B, "Pricing", 'Clean Data'!$C:$C, B10&" rent", 'Clean Data'!$D:$D, A10, 'Clean Data'!$E:$E, 2025) -> 4500000 | D10: =AVERAGEIFS('Clean Data'!$F:$F, 'Clean Data'!$B:$B, "Pricing", 'Clean Data'!$C:$C, B10&" rent", 'Clean Data'!$D:$D, A10, 'Clean Data'!$E:$E, 2026) -> 7000000 | E10: =AVERAGEIFS('Clean Data'!$F:$F, 'Clean Data'!$B:$B, "Pricing", 'Clean Data'!$C:$C, B10&" flat sale price", 'Clean Data'!$D:$D, A10, 'Clean Data'!$E:$E, 2025) -> 150000000 | F10: =AVERAGEIFS('Clean Data'!$F:$F, 'Clean Data'!$B:$B, "Pricing", 'Clean Data'!$C:$C, B10&" flat sale price", 'Clean Data'!$D:$D, A10, 'Clean Data'!$E:$E, 2026) -> 160000000 | G10: =IFERROR((D10-C10)/C10, "") -> 0.55555556 | H10: =IFERROR((F10-E10)/E10, "") -> 0.066666667 | I10: =IFERROR(D10/F10, "") -> 0.04375 | J10: =IFERROR(F10/D10, "") -> 22.857143
A11: Ikeja | B11: 1-bed | C11: =AVERAGEIFS('Clean Data'!$F:$F, 'Clean Data'!$B:$B, "Pricing", 'Clean Data'!$C:$C, B11&" rent", 'Clean Data'!$D:$D, A11, 'Clean Data'!$E:$E, 2025) -> 1800000 | D11: =AVERAGEIFS('Clean Data'!$F:$F, 'Clean Data'!$B:$B, "Pricing", 'Clean Data'!$C:$C, B11&" rent", 'Clean Data'!$D:$D, A11, 'Clean Data'!$E:$E, 2026) -> 2300000 | E11: =AVERAGEIFS('Clean Data'!$F:$F, 'Clean Data'!$B:$B, "Pricing", 'Clean Data'!$C:$C, B11&" flat sale price", 'Clean Data'!$D:$D, A11, 'Clean Data'!$E:$E, 2025) -> 50000000 | F11: =AVERAGEIFS('Clean Data'!$F:$F, 'Clean Data'!$B:$B, "Pricing", 'Clean Data'!$C:$C, B11&" flat sale price", 'Clean Data'!$D:$D, A11, 'Clean Data'!$E:$E, 2026) -> 95000000 | G11: =IFERROR((D11-C11)/C11, "") -> 0.27777778 | H11: =IFERROR((F11-E11)/E11, "") -> 0.9 | I11: =IFERROR(D11/F11, "") -> 0.024210526 | J11: =IFERROR(F11/D11, "") -> 41.304348
A12: Ikeja | B12: 2-bed | C12: =AVERAGEIFS('Clean Data'!$F:$F, 'Clean Data'!$B:$B, "Pricing", 'Clean Data'!$C:$C, B12&" rent", 'Clean Data'!$D:$D, A12, 'Clean Data'!$E:$E, 2025) -> 3000000 | D12: =AVERAGEIFS('Clean Data'!$F:$F, 'Clean Data'!$B:$B, "Pricing", 'Clean Data'!$C:$C, B12&" rent", 'Clean Data'!$D:$D, A12, 'Clean Data'!$E:$E, 2026) -> 4000000 | E12: =AVERAGEIFS('Clean Data'!$F:$F, 'Clean Data'!$B:$B, "Pricing", 'Clean Data'!$C:$C, B12&" flat sale price", 'Clean Data'!$D:$D, A12, 'Clean Data'!$E:$E, 2025) -> 140000000 | F12: =AVERAGEIFS('Clean Data'!$F:$F, 'Clean Data'!$B:$B, "Pricing", 'Clean Data'!$C:$C, B12&" flat sale price", 'Clean Data'!$D:$D, A12, 'Clean Data'!$E:$E, 2026) -> 165000000 | G12: =IFERROR((D12-C12)/C12, "") -> 0.33333333 | H12: =IFERROR((F12-E12)/E12, "") -> 0.17857143 | I12: =IFERROR(D12/F12, "") -> 0.024242424 | J12: =IFERROR(F12/D12, "") -> 41.25
A13: Ikeja | B13: 3-bed | C13: =AVERAGEIFS('Clean Data'!$F:$F, 'Clean Data'!$B:$B, "Pricing", 'Clean Data'!$C:$C, B13&" rent", 'Clean Data'!$D:$D, A13, 'Clean Data'!$E:$E, 2025) -> 6000000 | D13: =AVERAGEIFS('Clean Data'!$F:$F, 'Clean Data'!$B:$B, "Pricing", 'Clean Data'!$C:$C, B13&" rent", 'Clean Data'!$D:$D, A13, 'Clean Data'!$E:$E, 2026) -> 8500000 | E13: =AVERAGEIFS('Clean Data'!$F:$F, 'Clean Data'!$B:$B, "Pricing", 'Clean Data'!$C:$C, B13&" flat sale price", 'Clean Data'!$D:$D, A13, 'Clean Data'!$E:$E, 2025) -> 199000000 | F13: =AVERAGEIFS('Clean Data'!$F:$F, 'Clean Data'!$B:$B, "Pricing", 'Clean Data'!$C:$C, B13&" flat sale price", 'Clean Data'!$D:$D, A13, 'Clean Data'!$E:$E, 2026) -> 300000000 | G13: =IFERROR((D13-C13)/C13, "") -> 0.41666667 | H13: =IFERROR((F13-E13)/E13, "") -> 0.50753769 | I13: =IFERROR(D13/F13, "") -> 0.028333333 | J13: =IFERROR(F13/D13, "") -> 35.294118
... A22: Maryland | B22: 3-bed | C22: =AVERAGEIFS('Clean Data'!$F:$F, 'Clean Data'!$B:$B, "Pricing", 'Clean Data'!$C:$C, B22&" rent", 'Clean Data'!$D:$D, A22, 'Clean Data'!$E:$E, 2025) -> 7000000 | D22: =AVERAGEIFS('Clean Data'!$F:$F, 'Clean Data'!$B:$B, "Pricing", 'Clean Data'!$C:$C, B22&" rent", 'Clean Data'!$D:$D, A22, 'Clean Data'!$E:$E, 2026) -> 8000000 | E22: =AVERAGEIFS('Clean Data'!$F:$F, 'Clean Data'!$B:$B, "Pricing", 'Clean Data'!$C:$C, B22&" flat sale price", 'Clean Data'!$D:$D, A22, 'Clean Data'!$E:$E, 2025) -> 170000000 | F22: =AVERAGEIFS('Clean Data'!$F:$F, 'Clean Data'!$B:$B, "Pricing", 'Clean Data'!$C:$C, B22&" flat sale price", 'Clean Data'!$D:$D, A22, 'Clean Data'!$E:$E, 2026) -> 260000000 | G22: =IFERROR((D22-C22)/C22, "") -> 0.14285714 | H22: =IFERROR((F22-E22)/E22, "") -> 0.52941176 | I22: =IFERROR(D22/F22, "") -> 0.030769231 | J22: =IFERROR(F22/D22, "") -> 32.5
A25: Metric | B25: Value | D25: Metric | E25: Value
A26: Average Gross Yield | B26: =AVERAGE(I2:I22) -> 0.041655506 | D26: Gross Yield | E26: =AVERAGE(I2:I22) -> 0.041655506
A27: Average YoY Rent Growth | B27: =AVERAGE(G2:G22) -> 0.33605656 | D27: Inflation | E27: =AVERAGEIFS('Clean Data'!$F:$F, 'Clean Data'!$B:$B, "Macro", 'Clean Data'!$C:$C, "Inflation rate", 'Clean Data'!$E:$E, 2025)/100 -> 0.2301
A28: Average YoY Price Growth | B28: =AVERAGE(H2:H22) -> 0.40636648 | D28: MPR 2025 | E28: =AVERAGEIFS('Clean Data'!$F:$F, 'Clean Data'!$B:$B, "Macro", 'Clean Data'!$C:$C, "MPR (year-end)", 'Clean Data'!$E:$E, 2025) / 100 -> 0.27
A29: Inflation 2025 | B29: =AVERAGEIFS('Clean Data'!$F:$F, 'Clean Data'!$B:$B, "Macro", 'Clean Data'!$C:$C, "Inflation rate", 'Clean Data'!$E:$E, 2025)/100 -> 0.2301
A30: GDP Growth 2025 | B30: =AVERAGEIFS('Clean Data'!$F:$F, 'Clean Data'!$B:$B, "Macro", 'Clean Data'!$C:$C, "Real GDP growth", 'Clean Data'!$E:$E, 2025)/100 -> 0.0387
A31: MPR 2025 | B31: =AVERAGEIFS('Clean Data'!$F:$F, 'Clean Data'!$B:$B, "Macro", 'Clean Data'!$C:$C, "MPR (year-end)", 'Clean Data'!$E:$E, 2025) / 100 -> 0.27
A32: Real Yield Approximation (Gross Yield - Inflation) | B32: =B26-B29 -> -0.18844449 | C32: This is an approximation only. It compares average gross yield to headline inflation and does not represent a full inflation-adjusted investment return
A33: Housing Deficit | B33: =AVERAGEIFS('Clean Data'!$F:$F, 'Clean Data'!$B:$B, "Demand", 'Clean Data'!$C:$C, "Housing deficit", 'Clean Data'!$E:$E, 2026) / 1000000 -> 3.4
A36: Location | B36: 1-bed Avg Rent | C36: 2-bed Avg Rent | D36: 3-bed Avg Rent
A37: Yaba | B37: =AVERAGEIFS($D$2:$D$22, $A$2:$A$22, "Yaba", $B$2:$B$22, "1-bed") -> 2500000 | C37: =AVERAGEIFS($D$2:$D$22, $A$2:$A$22, "Yaba", $B$2:$B$22, "2-bed") -> 4500000 | D37: =AVERAGEIFS($D$2:$D$22, $A$2:$A$22, "Yaba", $B$2:$B$22, "3-bed") -> 6000000
A38: Surulere | B38: =AVERAGEIFS($D$2:$D$22, $A$2:$A$22, "Surulere", $B$2:$B$22, "1-bed") -> 2500000 | C38: =AVERAGEIFS($D$2:$D$22, $A$2:$A$22, "Surulere", $B$2:$B$22, "2-bed") -> 4250000 | D38: =AVERAGEIFS($D$2:$D$22, $A$2:$A$22, "Surulere", $B$2:$B$22, "3-bed") -> 5000000
A39: Gbagada | B39: =AVERAGEIFS($D$2:$D$22, $A$2:$A$22, "Gbagada", $B$2:$B$22, "1-bed") -> 2500000 | C39: =AVERAGEIFS($D$2:$D$22, $A$2:$A$22, "Gbagada", $B$2:$B$22, "2-bed") -> 4350000 | D39: =AVERAGEIFS($D$2:$D$22, $A$2:$A$22, "Gbagada", $B$2:$B$22, "3-bed") -> 7000000
A40: Ikeja | B40: =AVERAGEIFS($D$2:$D$22, $A$2:$A$22, "Ikeja", $B$2:$B$22, "1-bed") -> 2300000 | C40: =AVERAGEIFS($D$2:$D$22, $A$2:$A$22, "Ikeja", $B$2:$B$22, "2-bed") -> 4000000 | D40: =AVERAGEIFS($D$2:$D$22, $A$2:$A$22, "Ikeja", $B$2:$B$22, "3-bed") -> 8500000
A41: Lekki | B41: =AVERAGEIFS($D$2:$D$22, $A$2:$A$22, "Lekki", $B$2:$B$22, "1-bed") -> 4500000 | C41: =AVERAGEIFS($D$2:$D$22, $A$2:$A$22, "Lekki", $B$2:$B$22, "2-bed") -> 10000000 | D41: =AVERAGEIFS($D$2:$D$22, $A$2:$A$22, "Lekki", $B$2:$B$22, "3-bed") -> 15000000
A42: Ajah | B42: =AVERAGEIFS($D$2:$D$22, $A$2:$A$22, "Ajah", $B$2:$B$22, "1-bed") -> 1900000 | C42: =AVERAGEIFS($D$2:$D$22, $A$2:$A$22, "Ajah", $B$2:$B$22, "2-bed") -> 3000000 | D42: =AVERAGEIFS($D$2:$D$22, $A$2:$A$22, "Ajah", $B$2:$B$22, "3-bed") -> 4000000
A43: Maryland | B43: =AVERAGEIFS($D$2:$D$22, $A$2:$A$22, "Maryland", $B$2:$B$22, "1-bed") -> 3500000 | C43: =AVERAGEIFS($D$2:$D$22, $A$2:$A$22, "Maryland", $B$2:$B$22, "2-bed") -> 6000000 | D43: =AVERAGEIFS($D$2:$D$22, $A$2:$A$22, "Maryland", $B$2:$B$22, "3-bed") -> 8000000
A47: Location | B47: 1-bed Avg Rent | C47: 2-bed Avg Rent | D47: 3-bed Avg Rent
A48: Ajah | B48: =AVERAGEIFS($D$2:$D$22, $A$2:$A$22, "Ajah", $B$2:$B$22, "1-bed")/1000000 -> 1.9 | C48: =AVERAGEIFS($D$2:$D$22, $A$2:$A$22, "Ajah", $B$2:$B$22, "2-bed")/1000000 -> 3 | D48: =AVERAGEIFS($D$2:$D$22, $A$2:$A$22, "Ajah", $B$2:$B$22, "3-bed")/1000000 -> 4
A49: Gbagada | B49: =AVERAGEIFS($D$2:$D$22, $A$2:$A$22, "Gbagada", $B$2:$B$22, "1-bed")/1000000 -> 2.5 | C49: =AVERAGEIFS($D$2:$D$22, $A$2:$A$22, "Gbagada", $B$2:$B$22, "2-bed")/1000000 -> 4.35 | D49: =AVERAGEIFS($D$2:$D$22, $A$2:$A$22, "Gbagada", $B$2:$B$22, "3-bed")/1000000 -> 7
A50: Ikeja | B50: =AVERAGEIFS($D$2:$D$22, $A$2:$A$22, "Ikeja", $B$2:$B$22, "1-bed")/1000000 -> 2.3 | C50: =AVERAGEIFS($D$2:$D$22, $A$2:$A$22, "Ikeja", $B$2:$B$22, "2-bed")/1000000 -> 4 | D50: =AVERAGEIFS($D$2:$D$22, $A$2:$A$22, "Ikeja", $B$2:$B$22, "3-bed")/1000000 -> 8.5
A51: Lekki | B51: =AVERAGEIFS($D$2:$D$22, $A$2:$A$22, "Lekki", $B$2:$B$22, "1-bed")/1000000 -> 4.5 | C51: =AVERAGEIFS($D$2:$D$22, $A$2:$A$22, "Lekki", $B$2:$B$22, "2-bed")/1000000 -> 10 | D51: =AVERAGEIFS($D$2:$D$22, $A$2:$A$22, "Lekki", $B$2:$B$22, "3-bed")/1000000 -> 15
A52: Maryland | B52: =AVERAGEIFS($D$2:$D$22, $A$2:$A$22, "Maryland", $B$2:$B$22, "1-bed")/1000000 -> 3.5 | C52: =AVERAGEIFS($D$2:$D$22, $A$2:$A$22, "Maryland", $B$2:$B$22, "2-bed")/1000000 -> 6 | D52: =AVERAGEIFS($D$2:$D$22, $A$2:$A$22, "Maryland", $B$2:$B$22, "3-bed")/1000000 -> 8
A53: Surulere | B53: =AVERAGEIFS($D$2:$D$22, $A$2:$A$22, "Surulere", $B$2:$B$22, "1-bed")/1000000 -> 2.5 | C53: =AVERAGEIFS($D$2:$D$22, $A$2:$A$22, "Surulere", $B$2:$B$22, "2-bed")/1000000 -> 4.25 | D53: =AVERAGEIFS($D$2:$D$22, $A$2:$A$22, "Surulere", $B$2:$B$22, "3-bed")/1000000 -> 5
A54: Yaba | B54: =AVERAGEIFS($D$2:$D$22, $A$2:$A$22, "Yaba", $B$2:$B$22, "1-bed")/1000000 -> 2.5 | C54: =AVERAGEIFS($D$2:$D$22, $A$2:$A$22, "Yaba", $B$2:$B$22, "2-bed")/1000000 -> 4.5 | D54: =AVERAGEIFS($D$2:$D$22, $A$2:$A$22, "Yaba", $B$2:$B$22, "3-bed")/1000000 -> 6
A57: Location | B57: 2025 | C57: 2026 | D57: Rent Growth %
...

Sheet Dashboard
